Workbook

Sheet metas
A1: PAINEL DE INDICADORES | C1: Meta | E1: Realizado | F1: Próxima
A2: NÚCLEO DE GESTÃO | B2: NÚCLEO DE GESTÃO PARTICIPATIVA
A3: 6. CBH – Reunião Ordinária do Comitê | B3: Reunião Ordinária | C3: 160
B4: Ordinária 1 | C4: 40 | D4: =IFERROR(__xludf.DUMMYFUNCTION("FILTER(gest!B:C,(gest!A:A=A3)*(YEAR(gest!B:B)=YEAR(TODAY())))"),46079.0) -> 46079 | E4: =IFERROR(__xludf.DUMMYFUNCTION("""COMPUTED_VALUE"""),"34") -> 34 | F4: =IF(AND(ISBLANK(E4),NOT(ISBLANK(D4))),D4,"")
B5: Ordinária 2 | C5: 40 | D5: =IFERROR(__xludf.DUMMYFUNCTION("""COMPUTED_VALUE"""),46198.0) -> 46198 | F5: =IF(AND(ISBLANK(E5),NOT(ISBLANK(D5))),D5,"") -> 46198
B6: Ordinária 3 | C6: 40 | F6: =IF(AND(ISBLANK(E6),NOT(ISBLANK(D6))),D6,"")
B7: Ordinária 4 | C7: 40 | F7: =IF(AND(ISBLANK(E7),NOT(ISBLANK(D7))),D7,"")
A8: 7. CBH – Reunião Extraordinária do Comitê | B8: Reunião Extraordinária | C8: 160
B9: Extraordinária 1 | C9: 40 | D9: =IFERROR(__xludf.DUMMYFUNCTION("FILTER(gest!B:C,(gest!A:A=A8)*(YEAR(gest!B:B)=YEAR(TODAY())))"),46176.0) -> 46176 | E9: =IFERROR(__xludf.DUMMYFUNCTION("""COMPUTED_VALUE"""),"28") -> 28 | F9: =IF(AND(ISBLANK(E9),NOT(ISBLANK(D9))),D9,"")
B10: Extraordinária 2 | C10: 40 | F10: =IF(AND(ISBLANK(E10),NOT(ISBLANK(D10))),D10,"")
B11: Extraordinária 3 | C11: 40 | F11: =IF(AND(ISBLANK(E11),NOT(ISBLANK(D11))),D11,"")
B12: Extraordinária 4 | C12: 40 | F12: =IF(AND(ISBLANK(E12),NOT(ISBLANK(D12))),D12,"")
B13: Extraordinária 5 | C13: 40 | F13: =IF(AND(ISBLANK(E13),NOT(ISBLANK(D13))),D13,"")
A14: 12. CBH – Reunião do Fórum Cearense de Comitê | B14: Reunião do Fórum Cearense de Comitê | C14: 4 | E14: =COUNTA(E15:E18) -> 1
B15: FCCH 1 | D15: =IFERROR(__xludf.DUMMYFUNCTION("FILTER(gest!B:C,(gest!A:A=A14)*(YEAR(gest!B:B)=YEAR(TODAY())))"),46063.0) -> 46063 | E15: =IFERROR(__xludf.DUMMYFUNCTION("""COMPUTED_VALUE"""),"1") -> 1 | F15: =IF(AND(ISBLANK(E15),NOT(ISBLANK(D15))),D15,"")
B16: FCCH 2 | D16: =IFERROR(__xludf.DUMMYFUNCTION("""COMPUTED_VALUE"""),46189.0) -> 46189 | F16: =IF(AND(ISBLANK(E16),NOT(ISBLANK(D16))),D16,"") -> 46189
B17: FCCH 3 | F17: =IF(AND(ISBLANK(E17),NOT(ISBLANK(D17))),D17,"")
B18: FCCH 4 | F18: =IF(AND(ISBLANK(E18),NOT(ISBLANK(D18))),D18,"")
A19: 16. CG – Capacitação da Comissão Gestora | B19: Capacitação da Comissão Gestora | C19: 8 | E19: =COUNTIFS(gest!A:A,A19,gest!B:B,">="&DATE(YEAR(TODAY()),1,1),gest!B:B,"<="&TODAY()) -> 2
D20: =IFERROR(__xludf.DUMMYFUNCTION("FILTER(gest!B:C,(gest!A:A=A19)*(YEAR(gest!B:B)=YEAR(TODAY())))"),46087.0) -> 46087 | E20: =IFERROR(__xludf.DUMMYFUNCTION("""COMPUTED_VALUE"""),"8") -> 8
D21: =IFERROR(__xludf.DUMMYFUNCTION("""COMPUTED_VALUE"""),46090.0) -> 46090 | E21: =IFERROR(__xludf.DUMMYFUNCTION("""COMPUTED_VALUE"""),"6") -> 6
A29: 1. Alocação de água – Reunião de Alocação Participativa | B29: Alocação participativa | C29: 8 | E29: =COUNTIFS(gest!A:A,A29,gest!B:B,">="&DATE(YEAR(TODAY()),1,1),gest!B:B,"<="&TODAY()) -> 0
D30: =IFERROR(__xludf.DUMMYFUNCTION("FILTER(gest!B:C,(gest!A:A=A29)*(YEAR(gest!B:B)=YEAR(TODAY())))"),46203.0) -> 46203
D31: =IFERROR(__xludf.DUMMYFUNCTION("""COMPUTED_VALUE"""),46203.0) -> 46203
A39: 2. Alocação de água – Reunião de Acompanhamento da Operação | B39: Acompanhamento da Operação | C39: 8 | E39: =COUNTIFS(gest!A:A,A39,gest!B:B,">="&DATE(YEAR(TODAY()),1,1),gest!B:B,"<="&TODAY()) -> 0
D40: =IFERROR(__xludf.DUMMYFUNCTION("FILTER(gest!B:C,(gest!A:A=A39)*(YEAR(gest!B:B)=YEAR(TODAY())))"),"#N/A") -> #N/A
A49: 3. Alocação de água – Reunião de Avaliação da Operação | B49: Avaliação da Operação | C49: 8 | E49: =COUNTIFS(gest!A:A,A49,gest!B:B,">="&DATE(YEAR(TODAY()),1,1),gest!B:B,"<="&TODAY()) -> 10
D50: =IFERROR(__xludf.DUMMYFUNCTION("FILTER(gest!B:C,(gest!A:A=A49)*(YEAR(gest!B:B)=YEAR(TODAY())))"),46083.0) -> 46083 | E50: =IFERROR(__xludf.DUMMYFUNCTION("""COMPUTED_VALUE"""),"0") -> 0
D51: =IFERROR(__xludf.DUMMYFUNCTION("""COMPUTED_VALUE"""),46084.0) -> 46084
D52: =IFERROR(__xludf.DUMMYFUNCTION("""COMPUTED_VALUE"""),46085.0) -> 46085 | E52: =IFERROR(__xludf.DUMMYFUNCTION("""COMPUTED_VALUE"""),"5") -> 5
D53: =IFERROR(__xludf.DUMMYFUNCTION("""COMPUTED_VALUE"""),46086.0) -> 46086 | E53: =IFERROR(__xludf.DUMMYFUNCTION("""COMPUTED_VALUE"""),"10") -> 10
D54: =IFERROR(__xludf.DUMMYFUNCTION("""COMPUTED_VALUE"""),46087.0) -> 46087 | E54: =IFERROR(__xludf.DUMMYFUNCTION("""COMPUTED_VALUE"""),"8") -> 8
D55: =IFERROR(__xludf.DUMMYFUNCTION("""COMPUTED_VALUE"""),46090.0) -> 46090 | E55: =IFERROR(__xludf.DUMMYFUNCTION("""COMPUTED_VALUE"""),"5") -> 5
D56: =IFERROR(__xludf.DUMMYFUNCTION("""COMPUTED_VALUE"""),46091.0) -> 46091
D57: =IFERROR(__xludf.DUMMYFUNCTION("""COMPUTED_VALUE"""),46092.0) -> 46092 | E57: =IFERROR(__xludf.DUMMYFUNCTION("""COMPUTED_VALUE"""),"10") -> 10
D58: =IFERROR(__xludf.DUMMYFUNCTION("""COMPUTED_VALUE"""),46093.0) -> 46093
D59: =IFERROR(__xludf.DUMMYFUNCTION("""COMPUTED_VALUE"""),46093.0) -> 46093
A61: NÚCLEO DE OPERAÇÃO | B61: NÚCLEO DE OPERAÇÃO
A62: INDICADOR 1: CORREÇÃO DAS ANOMALIAS DE RESPONSABILIDADE DAS REGIONAIS (R) E DOS AGIRS (A) DAS BARRAGENS ESTADUAIS MONITORADAS PELA COGERH | B62: Anomalias Corrigidas | C62: 23 | E62: =SUM(E63:E64) -> 15
A63: Objetivos: Promover a Operação a Manutenção e a Segurança da Infraestrutura Hídrica da Companhia | B63: Anomalias - Regional | C63: 10 | E63: =IFERROR(__xludf.DUMMYFUNCTION("IMPORTRANGE(""https://docs.google.com/spreadsheets/d/1qH75nopdqebmsXi99R6n0ZSfkSWO3wqoz2qnUvKnI0w/edit?gid=1285399262#gid=1285399262"",""res!c6:c7"")"),6.0) -> 6
...

Sheet açudes
A1: =IFERROR(__xludf.DUMMYFUNCTION("IMPORTRANGE(""https://docs.google.com/spreadsheets/d/1U7xw4reZguSls-dnmJ8PgEtHEv2QU44KRoJGWbCA3sY/edit?gid=2350551#gid=2350551"", ""APORTES!C7:L14"")"),"GAMELEIRA") -> GAMELEIRA | B1: =IFERROR(__xludf.DUMMYFUNCTION("""COMPUTED_VALUE"""),"Itapipoca") -> Itapipoca | C1: =IFERROR(__xludf.DUMMYFUNCTION("""COMPUTED_VALUE"""),36.98) -> 36.98 | D1: =IFERROR(__xludf.DUMMYFUNCTION("""COMPUTED_VALUE"""),36.99) -> 36.99 | E1: =IFERROR(__xludf.DUMMYFUNCTION("""COMPUTED_VALUE"""),62759.0) -> 62759 | F1: =IFERROR(__xludf.DUMMYFUNCTION("""COMPUTED_VALUE"""),0.01) -> 0.01 | G1: =IFERROR(__xludf.DUMMYFUNCTION("""COMPUTED_VALUE"""),0.00224766633470441) -> 0.0022476663 | H1: =IFERROR(__xludf.DUMMYFUNCTION("""COMPUTED_VALUE"""),"#REF!") -> #REF! | I1: =IFERROR(__xludf.DUMMYFUNCTION("""COMPUTED_VALUE"""),27.86) -> 27.86 | J1: =IFERROR(__xludf.DUMMYFUNCTION("""COMPUTED_VALUE"""),99.78) -> 99.78
A2: =IFERROR(__xludf.DUMMYFUNCTION("""COMPUTED_VALUE"""),"MISSI") -> MISSI | B2: =IFERROR(__xludf.DUMMYFUNCTION("""COMPUTED_VALUE"""),"Miraíma") -> Miraíma | C2: =IFERROR(__xludf.DUMMYFUNCTION("""COMPUTED_VALUE"""),54.720000000000006) -> 54.72 | D2: =IFERROR(__xludf.DUMMYFUNCTION("""COMPUTED_VALUE"""),54.71) -> 54.71 | E2: =IFERROR(__xludf.DUMMYFUNCTION("""COMPUTED_VALUE"""),0.0) -> 0 | F2: =IFERROR(__xludf.DUMMYFUNCTION("""COMPUTED_VALUE"""),-0.01) -> -0.01 | G2: =IFERROR(__xludf.DUMMYFUNCTION("""COMPUTED_VALUE"""),0.0) -> 0 | H2: =IFERROR(__xludf.DUMMYFUNCTION("""COMPUTED_VALUE"""),"#REF!") -> #REF! | I2: =IFERROR(__xludf.DUMMYFUNCTION("""COMPUTED_VALUE"""),54.37) -> 54.37 | J2: =IFERROR(__xludf.DUMMYFUNCTION("""COMPUTED_VALUE"""),100.0) -> 100
A3: =IFERROR(__xludf.DUMMYFUNCTION("""COMPUTED_VALUE"""),"POÇO VERDE") -> POÇO VERDE | B3: =IFERROR(__xludf.DUMMYFUNCTION("""COMPUTED_VALUE"""),"Itapipoca") -> Itapipoca | C3: =IFERROR(__xludf.DUMMYFUNCTION("""COMPUTED_VALUE"""),68.09000000000006) -> 68.09 | D3: =IFERROR(__xludf.DUMMYFUNCTION("""COMPUTED_VALUE"""),68.09000000000006) -> 68.09 | E3: =IFERROR(__xludf.DUMMYFUNCTION("""COMPUTED_VALUE"""),0.0) -> 0 | F3: =IFERROR(__xludf.DUMMYFUNCTION("""COMPUTED_VALUE"""),0.0) -> 0 | G3: =IFERROR(__xludf.DUMMYFUNCTION("""COMPUTED_VALUE"""),0.0) -> 0 | H3: =IFERROR(__xludf.DUMMYFUNCTION("""COMPUTED_VALUE"""),"") | I3: =IFERROR(__xludf.DUMMYFUNCTION("""COMPUTED_VALUE"""),13.34) -> 13.34 | J3: =IFERROR(__xludf.DUMMYFUNCTION("""COMPUTED_VALUE"""),100.0) -> 100
A4: =IFERROR(__xludf.DUMMYFUNCTION("""COMPUTED_VALUE"""),"MUNDAÚ") -> MUNDAÚ | B4: =IFERROR(__xludf.DUMMYFUNCTION("""COMPUTED_VALUE"""),"Uruburetama") -> Uruburetama | C4: =IFERROR(__xludf.DUMMYFUNCTION("""COMPUTED_VALUE"""),166.49) -> 166.49 | D4: =IFERROR(__xludf.DUMMYFUNCTION("""COMPUTED_VALUE"""),166.48) -> 166.48 | E4: =IFERROR(__xludf.DUMMYFUNCTION("""COMPUTED_VALUE"""),0.0) -> 0 | F4: =IFERROR(__xludf.DUMMYFUNCTION("""COMPUTED_VALUE"""),-0.01) -> -0.01 | G4: =IFERROR(__xludf.DUMMYFUNCTION("""COMPUTED_VALUE"""),0.0) -> 0 | H4: =IFERROR(__xludf.DUMMYFUNCTION("""COMPUTED_VALUE"""),"#REF!") -> #REF! | I4: =IFERROR(__xludf.DUMMYFUNCTION("""COMPUTED_VALUE"""),21.3) -> 21.3 | J4: =IFERROR(__xludf.DUMMYFUNCTION("""COMPUTED_VALUE"""),100.0) -> 100
A5: =IFERROR(__xludf.DUMMYFUNCTION("""COMPUTED_VALUE"""),"QUANDÚ") -> QUANDÚ | B5: =IFERROR(__xludf.DUMMYFUNCTION("""COMPUTED_VALUE"""),"Itapipoca") -> Itapipoca | C5: =IFERROR(__xludf.DUMMYFUNCTION("""COMPUTED_VALUE"""),98.52) -> 98.52 | D5: =IFERROR(__xludf.DUMMYFUNCTION("""COMPUTED_VALUE"""),98.52) -> 98.52 | E5: =IFERROR(__xludf.DUMMYFUNCTION("""COMPUTED_VALUE"""),0.0) -> 0 | F5: =IFERROR(__xludf.DUMMYFUNCTION("""COMPUTED_VALUE"""),0.0) -> 0 | G5: =IFERROR(__xludf.DUMMYFUNCTION("""COMPUTED_VALUE"""),0.0) -> 0 | H5: =IFERROR(__xludf.DUMMYFUNCTION("""COMPUTED_VALUE"""),"") | I5: =IFERROR(__xludf.DUMMYFUNCTION("""COMPUTED_VALUE"""),2.45) -> 2.45 | J5: =IFERROR(__xludf.DUMMYFUNCTION("""COMPUTED_VALUE"""),100.0) -> 100
A6: =IFERROR(__xludf.DUMMYFUNCTION("""COMPUTED_VALUE"""),"S. PEDRO TIMBAÚBA") -> S. PEDRO TIMBAÚBA | B6: =IFERROR(__xludf.DUMMYFUNCTION("""COMPUTED_VALUE"""),"Miraíma") -> Miraíma | C6: =IFERROR(__xludf.DUMMYFUNCTION("""COMPUTED_VALUE"""),99.05) -> 99.05 | D6: =IFERROR(__xludf.DUMMYFUNCTION("""COMPUTED_VALUE"""),99.04) -> 99.04 | E6: =IFERROR(__xludf.DUMMYFUNCTION("""COMPUTED_VALUE"""),0.0) -> 0 | F6: =IFERROR(__xludf.DUMMYFUNCTION("""COMPUTED_VALUE"""),-0.01) -> -0.01 | G6: =IFERROR(__xludf.DUMMYFUNCTION("""COMPUTED_VALUE"""),0.0) -> 0 | H6: =IFERROR(__xludf.DUMMYFUNCTION("""COMPUTED_VALUE"""),"#REF!") -> #REF! | I6: =IFERROR(__xludf.DUMMYFUNCTION("""COMPUTED_VALUE"""),15.77) -> 15.77 | J6: =IFERROR(__xludf.DUMMYFUNCTION("""COMPUTED_VALUE"""),100.0) -> 100
A7: =IFERROR(__xludf.DUMMYFUNCTION("""COMPUTED_VALUE"""),"STO. ANTÔNIO DE ARACATIAÇU") -> STO. ANTÔNIO DE ARACATIAÇU | B7: =IFERROR(__xludf.DUMMYFUNCTION("""COMPUTED_VALUE"""),"Sobral") -> Sobral | C7: =IFERROR(__xludf.DUMMYFUNCTION("""COMPUTED_VALUE"""),92.67) -> 92.67 | D7: =IFERROR(__xludf.DUMMYFUNCTION("""COMPUTED_VALUE"""),92.65) -> 92.65 | E7: =IFERROR(__xludf.DUMMYFUNCTION("""COMPUTED_VALUE"""),-102653.0) -> -102653 | F7: =IFERROR(__xludf.DUMMYFUNCTION("""COMPUTED_VALUE"""),-0.02) -> -0.02 | G7: =IFERROR(__xludf.DUMMYFUNCTION("""COMPUTED_VALUE"""),-0.003580502267178235) -> -0.0035805023 | H7: =IFERROR(__xludf.DUMMYFUNCTION("""COMPUTED_VALUE"""),"#REF!") -> #REF! | I7: =IFERROR(__xludf.DUMMYFUNCTION("""COMPUTED_VALUE"""),26.88) -> 26.88 | J7: =IFERROR(__xludf.DUMMYFUNCTION("""COMPUTED_VALUE"""),93.74) -> 93.74
A8: =IFERROR(__xludf.DUMMYFUNCTION("""COMPUTED_VALUE"""),"PATOS") -> PATOS | B8: =IFERROR(__xludf.DUMMYFUNCTION("""COMPUTED_VALUE"""),"Sobral") -> Sobral | C8: =IFERROR(__xludf.DUMMYFUNCTION("""COMPUTED_VALUE"""),105.66) -> 105.66 | D8: =IFERROR(__xludf.DUMMYFUNCTION("""COMPUTED_VALUE"""),105.64) -> 105.64 | E8: =IFERROR(__xludf.DUMMYFUNCTION("""COMPUTED_VALUE"""),-38008.0) -> -38008 | F8: =IFERROR(__xludf.DUMMYFUNCTION("""COMPUTED_VALUE"""),-0.02) -> -0.02 | G8: =IFERROR(__xludf.DUMMYFUNCTION("""COMPUTED_VALUE"""),-0.0050341721854304635) -> -0.0050341722 | H8: =IFERROR(__xludf.DUMMYFUNCTION("""COMPUTED_VALUE"""),"#REF!") -> #REF! | I8: =IFERROR(__xludf.DUMMYFUNCTION("""COMPUTED_VALUE"""),6.87) -> 6.87 | J8: =IFERROR(__xludf.DUMMYFUNCTION("""COMPUTED_VALUE"""),90.94) -> 90.94

Sheet prog
A1: =IFERROR(__xludf.DUMMYFUNCTION("IMPORTRANGE(""https://docs.google.com/spreadsheets/d/1zaCmAHA_Hgob1ygsnCGPfEIosw5PR-DYRK7b89cprdc/edit?gid=1378782964#gid=1378782964"",""'Programação ITAPIPOCA'!A:E"")")," ")
B5: =IFERROR(__xludf.DUMMYFUNCTION("""COMPUTED_VALUE"""),"Gerência") -> Gerência | C5: =IFERROR(__xludf.DUMMYFUNCTION("""COMPUTED_VALUE"""),"Núcleo") -> Núcleo | D5: =IFERROR(__xludf.DUMMYFUNCTION("""COMPUTED_VALUE"""),"Eixo") -> Eixo | E5: =IFERROR(__xludf.DUMMYFUNCTION("""COMPUTED_VALUE"""),"Atividade") -> Atividade
E6: =IFERROR(__xludf.DUMMYFUNCTION("""COMPUTED_VALUE""")," ")
A7: =IFERROR(__xludf.DUMMYFUNCTION("""COMPUTED_VALUE"""),46027.0) -> 46027 | E7: =IFERROR(__xludf.DUMMYFUNCTION("""COMPUTED_VALUE"""),"Providenciar stories dos aniversariantes do mês de janeiro do CBH Litoral") -> Providenciar stories dos aniversariantes do mês de janeiro do CBH Litoral
A8: =IFERROR(__xludf.DUMMYFUNCTION("""COMPUTED_VALUE"""),46027.0) -> 46027 | E8: =IFERROR(__xludf.DUMMYFUNCTION("""COMPUTED_VALUE"""),"Organização de documentos para a mobilização de Diretoria") -> Organização de documentos para a mobilização de Diretoria
A9: =IFERROR(__xludf.DUMMYFUNCTION("""COMPUTED_VALUE"""),46027.0) -> 46027 | E9: =IFERROR(__xludf.DUMMYFUNCTION("""COMPUTED_VALUE"""),"Mobilização para a 1ª Reunião com a Diretoria do CBH Litoral") -> Mobilização para a 1ª Reunião com a Diretoria do CBH Litoral
A10: =IFERROR(__xludf.DUMMYFUNCTION("""COMPUTED_VALUE"""),46027.0) -> 46027 | E10: =IFERROR(__xludf.DUMMYFUNCTION("""COMPUTED_VALUE"""),"Faturamento (Coleta das leituras dos hidrômetros)") -> Faturamento (Coleta das leituras dos hidrômetros)
A11: =IFERROR(__xludf.DUMMYFUNCTION("""COMPUTED_VALUE"""),46027.0) -> 46027 | E11: =IFERROR(__xludf.DUMMYFUNCTION("""COMPUTED_VALUE"""),"Instrumentação dos açudes Missi e Poço Verde (Medidores de Vazão de Percolação)") -> Instrumentação dos açudes Missi e Poço Verde (Medidores de Vazão de Percolação)
A12: =IFERROR(__xludf.DUMMYFUNCTION("""COMPUTED_VALUE"""),46028.0) -> 46028 | E12: =IFERROR(__xludf.DUMMYFUNCTION("""COMPUTED_VALUE"""),"Publicar story do aniversário da Sra. Maria Ozani de Araújo Barros ") -> Publicar story do aniversário da Sra. Maria Ozani de Araújo Barros
A13: =IFERROR(__xludf.DUMMYFUNCTION("""COMPUTED_VALUE"""),46028.0) -> 46028 | E13: =IFERROR(__xludf.DUMMYFUNCTION("""COMPUTED_VALUE"""),"Produção de peça sobre a 1ª Reunião com a Diretoria do CBH Litoral") -> Produção de peça sobre a 1ª Reunião com a Diretoria do CBH Litoral
A14: =IFERROR(__xludf.DUMMYFUNCTION("""COMPUTED_VALUE"""),46028.0) -> 46028 | E14: =IFERROR(__xludf.DUMMYFUNCTION("""COMPUTED_VALUE"""),"Produção de apresentação das atividades realizadas em 2025") -> Produção de apresentação das atividades realizadas em 2025
A15: =IFERROR(__xludf.DUMMYFUNCTION("""COMPUTED_VALUE"""),46028.0) -> 46028 | E15: =IFERROR(__xludf.DUMMYFUNCTION("""COMPUTED_VALUE"""),"Planejamento comunicação do CBH Litoral") -> Planejamento comunicação do CBH Litoral
A16: =IFERROR(__xludf.DUMMYFUNCTION("""COMPUTED_VALUE"""),46028.0) -> 46028 | E16: =IFERROR(__xludf.DUMMYFUNCTION("""COMPUTED_VALUE"""),"Contato com a comunicação da SRH para gravação de vídeo sobre o Dia Internacional da Educação") -> Contato com a comunicação da SRH para gravação de vídeo sobre o Dia Internacional da Educação
A17: =IFERROR(__xludf.DUMMYFUNCTION("""COMPUTED_VALUE"""),46028.0) -> 46028 | E17: =IFERROR(__xludf.DUMMYFUNCTION("""COMPUTED_VALUE"""),"Faturamento (Coleta das leituras dos hidrômetros)") -> Faturamento (Coleta das leituras dos hidrômetros)
A18: =IFERROR(__xludf.DUMMYFUNCTION("""COMPUTED_VALUE"""),46028.0) -> 46028 | E18: =IFERROR(__xludf.DUMMYFUNCTION("""COMPUTED_VALUE"""),"Acompanhamento de Trecho Perenizado (Mundaú)") -> Acompanhamento de Trecho Perenizado (Mundaú)
A19: =IFERROR(__xludf.DUMMYFUNCTION("""COMPUTED_VALUE"""),46029.0) -> 46029 | E19: =IFERROR(__xludf.DUMMYFUNCTION("""COMPUTED_VALUE"""),"Produção de apresentação das atividades realizadas em 2025") -> Produção de apresentação das atividades realizadas em 2025
A20: =IFERROR(__xludf.DUMMYFUNCTION("""COMPUTED_VALUE"""),46029.0) -> 46029 | E20: =IFERROR(__xludf.DUMMYFUNCTION("""COMPUTED_VALUE"""),"Providenciar série de publicações sobre a campanha Janeiro Branco") -> Providenciar série de publicações sobre a campanha Janeiro Branco
A21: =IFERROR(__xludf.DUMMYFUNCTION("""COMPUTED_VALUE"""),46029.0) -> 46029 | E21: =IFERROR(__xludf.DUMMYFUNCTION("""COMPUTED_VALUE"""),"Faturamento (Coleta das leituras dos hidrômetros)") -> Faturamento (Coleta das leituras dos hidrômetros)
A22: =IFERROR(__xludf.DUMMYFUNCTION("""COMPUTED_VALUE"""),46029.0) -> 46029 | E22: =IFERROR(__xludf.DUMMYFUNCTION("""COMPUTED_VALUE"""),"Inspeção de Segurança Regular, Acompanhamento de Trecho Perenizado e Medição de Vazão (São Pedro da Timbaúba)") -> Inspeção de Segurança Regular, Acompanhamento de Trecho Perenizado e Medição de Vazão (São Pedro da Timbaúba)
A23: =IFERROR(__xludf.DUMMYFUNCTION("""COMPUTED_VALUE"""),46030.0) -> 46030 | E23: =IFERROR(__xludf.DUMMYFUNCTION("""COMPUTED_VALUE"""),"Oficina: Uso de IA no apoio à elaboração e padronização de atas e relatórios na COGERH") -> Oficina: Uso de IA no apoio à elaboração e padronização de atas e relatórios na COGERH
A24: =IFERROR(__xludf.DUMMYFUNCTION("""COMPUTED_VALUE"""),46030.0) -> 46030 | E24: =IFERROR(__xludf.DUMMYFUNCTION("""COMPUTED_VALUE"""),"Providenciar peça sobre emancipação do Estado do Ceará") -> Providenciar peça sobre emancipação do Estado do Ceará
A25: =IFERROR(__xludf.DUMMYFUNCTION("""COMPUTED_VALUE"""),46030.0) -> 46030 | E25: =IFERROR(__xludf.DUMMYFUNCTION("""COMPUTED_VALUE"""),"Faturamento (Coleta das leituras dos hidrômetros) e Vistoria no Trairi referente à contrução de um tanque") -> Faturamento (Coleta das leituras dos hidrômetros) e Vistoria no Trairi referente à contrução de um tanque
A26: =IFERROR(__xludf.DUMMYFUNCTION("""COMPUTED_VALUE"""),46030.0) -> 46030 | E26: =IFERROR(__xludf.DUMMYFUNCTION("""COMPUTED_VALUE"""),"Produção de Relatório de Acompanhamento de Trecho Perenizado (Mundaú e São Pedro da Timbaúba)") -> Produção de Relatório de Acompanhamento de Trecho Perenizado (Mundaú e São Pedro da Timbaúba)
A27: =IFERROR(__xludf.DUMMYFUNCTION("""COMPUTED_VALUE"""),46030.0) -> 46030 | E27: =IFERROR(__xludf.DUMMYFUNCTION("""COMPUTED_VALUE"""),"Inserir dados do Checklist no SIGERH (São Pedro da Timbaúba)") -> Inserir dados do Checklist no SIGERH (São Pedro da Timbaúba)
A28: =IFERROR(__xludf.DUMMYFUNCTION("""COMPUTED_VALUE"""),46031.0) -> 46031 | E28: =IFERROR(__xludf.DUMMYFUNCTION("""COMPUTED_VALUE"""),"Retorno da oficina: Uso de IA no apoio à elaboração e padronização de atas e relatórios na COGERH") -> Retorno da oficina: Uso de IA no apoio à elaboração e padronização de atas e relatórios na COGERH
A29: =IFERROR(__xludf.DUMMYFUNCTION("""COMPUTED_VALUE"""),46031.0) -> 46031 | E29: =IFERROR(__xludf.DUMMYFUNCTION("""COMPUTED_VALUE"""),"Produção de matéria sobre a 1ª Reunião com a Diretoria") -> Produção de matéria sobre a 1ª Reunião com a Diretoria
A30: =IFERROR(__xludf.DUMMYFUNCTION("""COMPUTED_VALUE"""),46031.0) -> 46031 | E30: =IFERROR(__xludf.DUMMYFUNCTION("""COMPUTED_VALUE"""),"Atualizar planilha da Gerência Regional com atividades programadas da semana") -> Atualizar planilha da Gerência Regional com atividades programadas da semana
A31: =IFERROR(__xludf.DUMMYFUNCTION("""COMPUTED_VALUE"""),46031.0) -> 46031 | E31: =IFERROR(__xludf.DUMMYFUNCTION("""COMPUTED_VALUE"""),"Atualizar planilha da Gestão Participativa com atividades programadas da semana") -> Atualizar planilha da Gestão Participativa com atividades programadas da semana
A32: =IFERROR(__xludf.DUMMYFUNCTION("""COMPUTED_VALUE"""),46031.0) -> 46031 | E32: =IFERROR(__xludf.DUMMYFUNCTION("""COMPUTED_VALUE"""),"Faturamento (Atualizar dados do faturamento no sistema)") -> Faturamento (Atualizar dados do faturamento no sistema)
A33: =IFERROR(__xludf.DUMMYFUNCTION("""COMPUTED_VALUE"""),46031.0) -> 46031 | E33: =IFERROR(__xludf.DUMMYFUNCTION("""COMPUTED_VALUE"""),"Vistoria de Usuários (DASS)") -> Vistoria de Usuários (DASS)
A34: =IFERROR(__xludf.DUMMYFUNCTION("""COMPUTED_VALUE"""),46031.0) -> 46031 | E34: =IFERROR(__xludf.DUMMYFUNCTION("""COMPUTED_VALUE"""),"Produção do relatório de vistoria na DASS") -> Produção do relatório de vistoria na DASS
A35: =IFERROR(__xludf.DUMMYFUNCTION("""COMPUTED_VALUE"""),46031.0) -> 46031 | E35: =IFERROR(__xludf.DUMMYFUNCTION("""COMPUTED_VALUE"""),"Atualização dos dados de Captação e Perenização no SIGERH") -> Atualização dos dados de Captação e Perenização no SIGERH
A36: =IFERROR(__xludf.DUMMYFUNCTION("""COMPUTED_VALUE"""),46031.0) -> 46031 | E36: =IFERROR(__xludf.DUMMYFUNCTION("""COMPUTED_VALUE"""),"Instrumentação dos açudes Missi e Poço Verde (Medidores de Vazão de Percolação)") -> Instrumentação dos açudes Missi e Poço Verde (Medidores de Vazão de Percolação)
A37: =IFERROR(__xludf.DUMMYFUNCTION("""COMPUTED_VALUE"""),46032.0) -> 46032
A38: =IFERROR(__xludf.DUMMYFUNCTION("""COMPUTED_VALUE"""),46033.0) -> 46033
A39: =IFERROR(__xludf.DUMMYFUNCTION("""COMPUTED_VALUE"""),46034.0) -> 46034 | E39: =IFERROR(__xludf.DUMMYFUNCTION("""COMPUTED_VALUE"""),"Diagnóstico CG do açude Patos") -> Diagnóstico CG do açude Patos
A40: =IFERROR(__xludf.DUMMYFUNCTION("""COMPUTED_VALUE"""),46034.0) -> 46034 | E40: =IFERROR(__xludf.DUMMYFUNCTION("""COMPUTED_VALUE"""),"Atualizar contatos das Câmaras e Prefeituras Municipais dos 13 municípios da Bacia Hidrográfica") -> Atualizar contatos das Câmaras e Prefeituras Municipais dos 13 municípios da Bacia Hidrográfica
A41: =IFERROR(__xludf.DUMMYFUNCTION("""COMPUTED_VALUE"""),46034.0) -> 46034 | E41: =IFERROR(__xludf.DUMMYFUNCTION("""COMPUTED_VALUE"""),"Organizar rota de mobilizações para a 74ª Reunião Ordinária") -> Organizar rota de mobilizações para a 74ª Reunião Ordinária
A42: =IFERROR(__xludf.DUMMYFUNCTION("""COMPUTED_VALUE"""),46034.0) -> 46034 | E42: =IFERROR(__xludf.DUMMYFUNCTION("""COMPUTED_VALUE"""),"Comunicar os membros que gravarão os vídeos dos aniversários municipais de Itarema e Amontada, respectivamente") -> Comunicar os membros que gravarão os vídeos dos aniversários municipais de Itarema e Amontada, respectivamente
A43: =IFERROR(__xludf.DUMMYFUNCTION("""COMPUTED_VALUE"""),46034.0) -> 46034 | E43: =IFERROR(__xludf.DUMMYFUNCTION("""COMPUTED_VALUE"""),"Produção de post com legenda sobre 74ª Reunião Ordinária do CBH Litoral") -> Produção de post com legenda sobre 74ª Reunião Ordinária do CBH Litoral
...

Sheet oper
A1: FISCALIZAÇÃO
A2: =IFERROR(__xludf.DUMMYFUNCTION("IMPORTRANGE(""https://docs.google.com/spreadsheets/d/1iBrpLlm14k9_yhp3qCf1sI5I4CW0_hVvSluhMLtsnf0/edit?gid=874251860#gid=874251860"",""Indicador Setorial!b4:O4"")"),105.0) -> 105 | B2: =IFERROR(__xludf.DUMMYFUNCTION("""COMPUTED_VALUE"""),38.0) -> 38 | C2: =IFERROR(__xludf.DUMMYFUNCTION("""COMPUTED_VALUE"""),7.0) -> 7 | D2: =IFERROR(__xludf.DUMMYFUNCTION("""COMPUTED_VALUE"""),4.0) -> 4 | E2: =IFERROR(__xludf.DUMMYFUNCTION("""COMPUTED_VALUE"""),8.0) -> 8 | F2: =IFERROR(__xludf.DUMMYFUNCTION("""COMPUTED_VALUE"""),9.0) -> 9 | G2: =IFERROR(__xludf.DUMMYFUNCTION("""COMPUTED_VALUE"""),10.0) -> 10 | H2: =IFERROR(__xludf.DUMMYFUNCTION("""COMPUTED_VALUE"""),0.0) -> 0 | I2: =IFERROR(__xludf.DUMMYFUNCTION("""COMPUTED_VALUE"""),0.0) -> 0 | J2: =IFERROR(__xludf.DUMMYFUNCTION("""COMPUTED_VALUE"""),0.0) -> 0 | K2: =IFERROR(__xludf.DUMMYFUNCTION("""COMPUTED_VALUE"""),0.0) -> 0 | L2: =IFERROR(__xludf.DUMMYFUNCTION("""COMPUTED_VALUE"""),0.0) -> 0 | M2: =IFERROR(__xludf.DUMMYFUNCTION("""COMPUTED_VALUE"""),0.0) -> 0 | N2: =IFERROR(__xludf.DUMMYFUNCTION("""COMPUTED_VALUE"""),0.0) -> 0 | O2: SEM RV
C3: =IFERROR(__xludf.DUMMYFUNCTION("IMPORTRANGE(""https://docs.google.com/spreadsheets/d/1iBrpLlm14k9_yhp3qCf1sI5I4CW0_hVvSluhMLtsnf0/edit?gid=874251860#gid=874251860"",""Indicador Setorial!d31:31"")"),5.0) -> 5 | D3: =IFERROR(__xludf.DUMMYFUNCTION("""COMPUTED_VALUE"""),3.0) -> 3 | E3: =IFERROR(__xludf.DUMMYFUNCTION("""COMPUTED_VALUE"""),5.0) -> 5 | F3: =IFERROR(__xludf.DUMMYFUNCTION("""COMPUTED_VALUE"""),0.0) -> 0 | G3: =IFERROR(__xludf.DUMMYFUNCTION("""COMPUTED_VALUE"""),0.0) -> 0 | H3: =IFERROR(__xludf.DUMMYFUNCTION("""COMPUTED_VALUE"""),0.0) -> 0 | I3: =IFERROR(__xludf.DUMMYFUNCTION("""COMPUTED_VALUE"""),0.0) -> 0 | J3: =IFERROR(__xludf.DUMMYFUNCTION("""COMPUTED_VALUE"""),0.0) -> 0 | K3: =IFERROR(__xludf.DUMMYFUNCTION("""COMPUTED_VALUE"""),0.0) -> 0 | L3: =IFERROR(__xludf.DUMMYFUNCTION("""COMPUTED_VALUE"""),0.0) -> 0 | M3: =IFERROR(__xludf.DUMMYFUNCTION("""COMPUTED_VALUE"""),0.0) -> 0 | N3: =IFERROR(__xludf.DUMMYFUNCTION("""COMPUTED_VALUE"""),0.0) -> 0 | O3: =IFERROR(__xludf.DUMMYFUNCTION("""COMPUTED_VALUE"""),13.0) -> 13
A5: MANUTENÇÃO E INSTALAÇÃO:
C6: =IFERROR(__xludf.DUMMYFUNCTION("IMPORTRANGE(""https://docs.google.com/spreadsheets/d/1ZMQ1ZJd0nWMp1bKte4MwmpuiYfPuptkAdyS2OLhz2tY/edit?gid=867584558#gid=867584558"",""Itapipoca!B1:G1"")"),"MEDIÇÕES DE VAZÃO (MEDV)") -> MEDIÇÕES DE VAZÃO (MEDV) | D6: =IFERROR(__xludf.DUMMYFUNCTION("""COMPUTED_VALUE"""),"MEDIÇÕES COMPARATIVAS (MEDC)") -> MEDIÇÕES COMPARATIVAS (MEDC) | E6: =IFERROR(__xludf.DUMMYFUNCTION("""COMPUTED_VALUE"""),"MANUTENÇÕES DE HORIMETROS (MANH)") -> MANUTENÇÕES DE HORIMETROS (MANH) | F6: =IFERROR(__xludf.DUMMYFUNCTION("""COMPUTED_VALUE"""),"MANUTENÇÕES DE MEDIDORES (MANM)") -> MANUTENÇÕES DE MEDIDORES (MANM) | G6: =IFERROR(__xludf.DUMMYFUNCTION("""COMPUTED_VALUE"""),"INSTALAÇÕES DE HORIMETROS (INSH)") -> INSTALAÇÕES DE HORIMETROS (INSH) | H6: =IFERROR(__xludf.DUMMYFUNCTION("""COMPUTED_VALUE"""),"INSTALAÇÕES DE MEDIDORES (INSM)") -> INSTALAÇÕES DE MEDIDORES (INSM)
C7: =IFERROR(__xludf.DUMMYFUNCTION("IMPORTRANGE(""https://docs.google.com/spreadsheets/d/1ZMQ1ZJd0nWMp1bKte4MwmpuiYfPuptkAdyS2OLhz2tY/edit?gid=867584558#gid=867584558"",""Itapipoca!B14:G14"")"),6.0) -> 6 | D7: =IFERROR(__xludf.DUMMYFUNCTION("""COMPUTED_VALUE"""),5.0) -> 5 | E7: =IFERROR(__xludf.DUMMYFUNCTION("""COMPUTED_VALUE"""),1.0) -> 1 | F7: =IFERROR(__xludf.DUMMYFUNCTION("""COMPUTED_VALUE"""),3.0) -> 3 | G7: =IFERROR(__xludf.DUMMYFUNCTION("""COMPUTED_VALUE"""),1.0) -> 1 | H7: =IFERROR(__xludf.DUMMYFUNCTION("""COMPUTED_VALUE"""),2.0) -> 2
C8: =SUM(C7:D7) -> 11 | D8: =SUM(E7:F7) -> 4 | E8: =SUM(G7:H7) -> 3 | F8: =IFERROR(__xludf.DUMMYFUNCTION("IMPORTRANGE(""https://docs.google.com/spreadsheets/d/1ZMQ1ZJd0nWMp1bKte4MwmpuiYfPuptkAdyS2OLhz2tY/edit?gid=867584558#gid=867584558"",""Itapipoca!I14"")"),0.11) -> 0.11

Sheet gest
A1: =IFERROR(__xludf.DUMMYFUNCTION("QUERY(IMPORTRANGE(""https://docs.google.com/spreadsheets/d/1sXeXTD5YjBI3DqtVddm1VCMTInMYB4QnHol-BTa5xeo/edit"", ""Programação_Litoral!A:O""), ""SELECT Col4, Col2, Col13"", 1)"),"")
A6: =IFERROR(__xludf.DUMMYFUNCTION("""COMPUTED_VALUE"""),"Atividade") -> Atividade | C6: =IFERROR(__xludf.DUMMYFUNCTION("""COMPUTED_VALUE"""),"Nº de instituições Membros") -> Nº de instituições Membros
A7: =IFERROR(__xludf.DUMMYFUNCTION("""COMPUTED_VALUE"""),"20. Ação de Comunicação / Informação / Capacitação Externa") -> 20. Ação de Comunicação / Informação / Capacitação Externa | B7: =IFERROR(__xludf.DUMMYFUNCTION("""COMPUTED_VALUE"""),44928.0) -> 44928 | C7: =IFERROR(__xludf.DUMMYFUNCTION("""COMPUTED_VALUE"""),"40") -> 40
A8: =IFERROR(__xludf.DUMMYFUNCTION("""COMPUTED_VALUE"""),"20. Ação de Comunicação / Informação / Capacitação Externa") -> 20. Ação de Comunicação / Informação / Capacitação Externa | B8: =IFERROR(__xludf.DUMMYFUNCTION("""COMPUTED_VALUE"""),44928.0) -> 44928
A9: =IFERROR(__xludf.DUMMYFUNCTION("""COMPUTED_VALUE"""),"20. Ação de Comunicação / Informação / Capacitação Externa") -> 20. Ação de Comunicação / Informação / Capacitação Externa
A10: =IFERROR(__xludf.DUMMYFUNCTION("""COMPUTED_VALUE"""),"24. Projetos ou atividades Específicos") -> 24. Projetos ou atividades Específicos | B10: =IFERROR(__xludf.DUMMYFUNCTION("""COMPUTED_VALUE"""),44930.0) -> 44930 | C10: =IFERROR(__xludf.DUMMYFUNCTION("""COMPUTED_VALUE"""),"2") -> 2
A11: =IFERROR(__xludf.DUMMYFUNCTION("""COMPUTED_VALUE"""),"8. CBH – Reunião de Diretoria do CBH") -> 8. CBH – Reunião de Diretoria do CBH | B11: =IFERROR(__xludf.DUMMYFUNCTION("""COMPUTED_VALUE"""),44931.0) -> 44931 | C11: =IFERROR(__xludf.DUMMYFUNCTION("""COMPUTED_VALUE"""),"4") -> 4
A12: =IFERROR(__xludf.DUMMYFUNCTION("""COMPUTED_VALUE"""),"24. Projetos ou atividades Específicos") -> 24. Projetos ou atividades Específicos | B12: =IFERROR(__xludf.DUMMYFUNCTION("""COMPUTED_VALUE"""),44931.0) -> 44931
A13: =IFERROR(__xludf.DUMMYFUNCTION("""COMPUTED_VALUE"""),"24. Projetos ou atividades Específicos") -> 24. Projetos ou atividades Específicos | B13: =IFERROR(__xludf.DUMMYFUNCTION("""COMPUTED_VALUE"""),44934.0) -> 44934
A14: =IFERROR(__xludf.DUMMYFUNCTION("""COMPUTED_VALUE"""),"24. Projetos ou atividades Específicos") -> 24. Projetos ou atividades Específicos | B14: =IFERROR(__xludf.DUMMYFUNCTION("""COMPUTED_VALUE"""),44935.0) -> 44935 | C14: =IFERROR(__xludf.DUMMYFUNCTION("""COMPUTED_VALUE"""),"1") -> 1
A15: =IFERROR(__xludf.DUMMYFUNCTION("""COMPUTED_VALUE"""),"24. Projetos ou atividades Específicos") -> 24. Projetos ou atividades Específicos | B15: =IFERROR(__xludf.DUMMYFUNCTION("""COMPUTED_VALUE"""),44935.0) -> 44935 | C15: =IFERROR(__xludf.DUMMYFUNCTION("""COMPUTED_VALUE"""),"1") -> 1
A16: =IFERROR(__xludf.DUMMYFUNCTION("""COMPUTED_VALUE"""),"9. CBH – Reunião de Câmara Técnica, Câmara específica ou GT") -> 9. CBH – Reunião de Câmara Técnica, Câmara específica ou GT | B16: =IFERROR(__xludf.DUMMYFUNCTION("""COMPUTED_VALUE"""),44936.0) -> 44936 | C16: =IFERROR(__xludf.DUMMYFUNCTION("""COMPUTED_VALUE"""),"4") -> 4
A17: =IFERROR(__xludf.DUMMYFUNCTION("""COMPUTED_VALUE"""),"24. Projetos ou atividades Específicos") -> 24. Projetos ou atividades Específicos | B17: =IFERROR(__xludf.DUMMYFUNCTION("""COMPUTED_VALUE"""),44936.0) -> 44936 | C17: =IFERROR(__xludf.DUMMYFUNCTION("""COMPUTED_VALUE"""),"2") -> 2
A18: =IFERROR(__xludf.DUMMYFUNCTION("""COMPUTED_VALUE"""),"26. Outro") -> 26. Outro | B18: =IFERROR(__xludf.DUMMYFUNCTION("""COMPUTED_VALUE"""),44937.0) -> 44937
A19: =IFERROR(__xludf.DUMMYFUNCTION("""COMPUTED_VALUE"""),"25. Atividade Relacinada a Cobrança/Faturamento") -> 25. Atividade Relacinada a Cobrança/Faturamento | B19: =IFERROR(__xludf.DUMMYFUNCTION("""COMPUTED_VALUE"""),44937.0) -> 44937
A20: =IFERROR(__xludf.DUMMYFUNCTION("""COMPUTED_VALUE"""),"24. Projetos ou atividades Específicos") -> 24. Projetos ou atividades Específicos | B20: =IFERROR(__xludf.DUMMYFUNCTION("""COMPUTED_VALUE"""),44938.0) -> 44938
A21: =IFERROR(__xludf.DUMMYFUNCTION("""COMPUTED_VALUE"""),"24. Projetos ou atividades Específicos") -> 24. Projetos ou atividades Específicos | B21: =IFERROR(__xludf.DUMMYFUNCTION("""COMPUTED_VALUE"""),44942.0) -> 44942
A22: =IFERROR(__xludf.DUMMYFUNCTION("""COMPUTED_VALUE"""),"6. CBH – Reunião Ordinária do Comitê") -> 6. CBH – Reunião Ordinária do Comitê | B22: =IFERROR(__xludf.DUMMYFUNCTION("""COMPUTED_VALUE"""),44942.0) -> 44942
A23: =IFERROR(__xludf.DUMMYFUNCTION("""COMPUTED_VALUE"""),"20. Ação de Comunicação / Informação / Capacitação Externa") -> 20. Ação de Comunicação / Informação / Capacitação Externa | B23: =IFERROR(__xludf.DUMMYFUNCTION("""COMPUTED_VALUE"""),44943.0) -> 44943
A24: =IFERROR(__xludf.DUMMYFUNCTION("""COMPUTED_VALUE"""),"24. Projetos ou atividades Específicos") -> 24. Projetos ou atividades Específicos | B24: =IFERROR(__xludf.DUMMYFUNCTION("""COMPUTED_VALUE"""),44943.0) -> 44943 | C24: =IFERROR(__xludf.DUMMYFUNCTION("""COMPUTED_VALUE"""),"1") -> 1
A25: =IFERROR(__xludf.DUMMYFUNCTION("""COMPUTED_VALUE"""),"24. Projetos ou atividades Específicos") -> 24. Projetos ou atividades Específicos | B25: =IFERROR(__xludf.DUMMYFUNCTION("""COMPUTED_VALUE"""),44944.0) -> 44944
A26: =IFERROR(__xludf.DUMMYFUNCTION("""COMPUTED_VALUE"""),"12. CBH – Reunião do Fórum Cearense de Comitê") -> 12. CBH – Reunião do Fórum Cearense de Comitê | B26: =IFERROR(__xludf.DUMMYFUNCTION("""COMPUTED_VALUE"""),44949.0) -> 44949 | C26: =IFERROR(__xludf.DUMMYFUNCTION("""COMPUTED_VALUE"""),"3") -> 3
A27: =IFERROR(__xludf.DUMMYFUNCTION("""COMPUTED_VALUE"""),"18. Mobilização Social") -> 18. Mobilização Social | B27: =IFERROR(__xludf.DUMMYFUNCTION("""COMPUTED_VALUE"""),44951.0) -> 44951 | C27: =IFERROR(__xludf.DUMMYFUNCTION("""COMPUTED_VALUE"""),"29") -> 29
A28: =IFERROR(__xludf.DUMMYFUNCTION("""COMPUTED_VALUE"""),"Apoio ao Comitê de Bacias") -> Apoio ao Comitê de Bacias | B28: =IFERROR(__xludf.DUMMYFUNCTION("""COMPUTED_VALUE"""),44958.0) -> 44958 | C28: =IFERROR(__xludf.DUMMYFUNCTION("""COMPUTED_VALUE"""),"40") -> 40
A29: =IFERROR(__xludf.DUMMYFUNCTION("""COMPUTED_VALUE"""),"17. CG – Apoio à Formação de CG nos reservatórios (e renovação)") -> 17. CG – Apoio à Formação de CG nos reservatórios (e renovação) | B29: =IFERROR(__xludf.DUMMYFUNCTION("""COMPUTED_VALUE"""),44960.0) -> 44960 | C29: =IFERROR(__xludf.DUMMYFUNCTION("""COMPUTED_VALUE"""),"3") -> 3
A30: =IFERROR(__xludf.DUMMYFUNCTION("""COMPUTED_VALUE"""),"62ª Reunião Ordinária do CBH Litoral") -> 62ª Reunião Ordinária do CBH Litoral | B30: =IFERROR(__xludf.DUMMYFUNCTION("""COMPUTED_VALUE"""),44965.0) -> 44965 | C30: =IFERROR(__xludf.DUMMYFUNCTION("""COMPUTED_VALUE"""),"37") -> 37
A31: =IFERROR(__xludf.DUMMYFUNCTION("""COMPUTED_VALUE"""),"10. CBH – Capacitação do Comitê") -> 10. CBH – Capacitação do Comitê | B31: =IFERROR(__xludf.DUMMYFUNCTION("""COMPUTED_VALUE"""),44965.0) -> 44965 | C31: =IFERROR(__xludf.DUMMYFUNCTION("""COMPUTED_VALUE"""),"37") -> 37
A32: =IFERROR(__xludf.DUMMYFUNCTION("""COMPUTED_VALUE"""),"Apoio ao Comitê") -> Apoio ao Comitê | B32: =IFERROR(__xludf.DUMMYFUNCTION("""COMPUTED_VALUE"""),44966.0) -> 44966
A33: =IFERROR(__xludf.DUMMYFUNCTION("""COMPUTED_VALUE"""),"Apoio ao Comitê") -> Apoio ao Comitê | B33: =IFERROR(__xludf.DUMMYFUNCTION("""COMPUTED_VALUE"""),44966.0) -> 44966
A34: =IFERROR(__xludf.DUMMYFUNCTION("""COMPUTED_VALUE"""),"17. CG – Apoio à Formação de CG nos reservatórios (e renovação)") -> 17. CG – Apoio à Formação de CG nos reservatórios (e renovação) | B34: =IFERROR(__xludf.DUMMYFUNCTION("""COMPUTED_VALUE"""),44971.0) -> 44971 | C34: =IFERROR(__xludf.DUMMYFUNCTION("""COMPUTED_VALUE"""),"2") -> 2
A35: =IFERROR(__xludf.DUMMYFUNCTION("""COMPUTED_VALUE"""),"17. CG – Apoio à Formação de CG nos reservatórios (e renovação)") -> 17. CG – Apoio à Formação de CG nos reservatórios (e renovação) | B35: =IFERROR(__xludf.DUMMYFUNCTION("""COMPUTED_VALUE"""),44972.0) -> 44972
A36: =IFERROR(__xludf.DUMMYFUNCTION("""COMPUTED_VALUE"""),"18. Mobilização Social") -> 18. Mobilização Social | B36: =IFERROR(__xludf.DUMMYFUNCTION("""COMPUTED_VALUE"""),44980.0) -> 44980
A37: =IFERROR(__xludf.DUMMYFUNCTION("""COMPUTED_VALUE"""),"18. Mobilização Social") -> 18. Mobilização Social | B37: =IFERROR(__xludf.DUMMYFUNCTION("""COMPUTED_VALUE"""),44984.0) -> 44984
A38: =IFERROR(__xludf.DUMMYFUNCTION("""COMPUTED_VALUE"""),"17. CG – Apoio à Formação de CG nos reservatórios (e renovação)") -> 17. CG – Apoio à Formação de CG nos reservatórios (e renovação) | B38: =IFERROR(__xludf.DUMMYFUNCTION("""COMPUTED_VALUE"""),44985.0) -> 44985
A39: =IFERROR(__xludf.DUMMYFUNCTION("""COMPUTED_VALUE"""),"20. Ação de Comunicação / Informação / Capacitação Externa") -> 20. Ação de Comunicação / Informação / Capacitação Externa | B39: =IFERROR(__xludf.DUMMYFUNCTION("""COMPUTED_VALUE"""),44986.0) -> 44986 | C39: =IFERROR(__xludf.DUMMYFUNCTION("""COMPUTED_VALUE"""),"40") -> 40
A40: =IFERROR(__xludf.DUMMYFUNCTION("""COMPUTED_VALUE"""),"20. Ação de Comunicação / Informação / Capacitação Externa") -> 20. Ação de Comunicação / Informação / Capacitação Externa | B40: =IFERROR(__xludf.DUMMYFUNCTION("""COMPUTED_VALUE"""),44986.0) -> 44986 | C40: =IFERROR(__xludf.DUMMYFUNCTION("""COMPUTED_VALUE"""),"15") -> 15
A41: =IFERROR(__xludf.DUMMYFUNCTION("""COMPUTED_VALUE"""),"24. Projetos ou atividades Específicos") -> 24. Projetos ou atividades Específicos | B41: =IFERROR(__xludf.DUMMYFUNCTION("""COMPUTED_VALUE"""),44986.0) -> 44986 | C41: =IFERROR(__xludf.DUMMYFUNCTION("""COMPUTED_VALUE"""),"1") -> 1
A42: =IFERROR(__xludf.DUMMYFUNCTION("""COMPUTED_VALUE"""),"18. Mobilização Social") -> 18. Mobilização Social | B42: =IFERROR(__xludf.DUMMYFUNCTION("""COMPUTED_VALUE"""),44986.0) -> 44986 | C42: =IFERROR(__xludf.DUMMYFUNCTION("""COMPUTED_VALUE"""),"40") -> 40
A43: =IFERROR(__xludf.DUMMYFUNCTION("""COMPUTED_VALUE"""),"18. Mobilização Social") -> 18. Mobilização Social | B43: =IFERROR(__xludf.DUMMYFUNCTION("""COMPUTED_VALUE"""),44986.0) -> 44986 | C43: =IFERROR(__xludf.DUMMYFUNCTION("""COMPUTED_VALUE"""),"7") -> 7
A44: =IFERROR(__xludf.DUMMYFUNCTION("""COMPUTED_VALUE"""),"18. Mobilização Social") -> 18. Mobilização Social | B44: =IFERROR(__xludf.DUMMYFUNCTION("""COMPUTED_VALUE"""),44986.0) -> 44986 | C44: =IFERROR(__xludf.DUMMYFUNCTION("""COMPUTED_VALUE"""),"6") -> 6
...
